ERROR 2024-10-30 19:46:14,928 log Internal Server Error: /teacher/repository/exercise_list/create_exercise/61/
Traceback (most recent call last):
  File "D:\GitHub\Project\Software_cup\venv\Lib\site-packages\django\template\base.py", line 502, in parse
    compile_func = self.tags[command]
                   ~~~~~~~~~^^^^^^^^^
KeyError: 'static'

During handling of the above exception, another exception occurred:

Traceback (most recent call last):
  File "D:\GitHub\Project\Software_cup\venv\Lib\site-packages\django\core\handlers\exception.py", line 55, in inner
    response = get_response(request)
               ^^^^^^^^^^^^^^^^^^^^^
  File "D:\GitHub\Project\Software_cup\venv\Lib\site-packages\django\core\handlers\base.py", line 197, in _get_response
    response = wrapped_callback(request, *callback_args, **callback_kwargs)
               ^^^^^^^^^^^^^^^^^^^^^^^^^^^^^^^^^^^^^^^^^^^^^^^^^^^^^^^^^^^^
  File "D:\GitHub\Project\Software_cup\login\views.py", line 88, in wrapper
    return view_func(request, *args, **kwargs)
           ^^^^^^^^^^^^^^^^^^^^^^^^^^^^^^^^^^^
  File "D:\GitHub\Project\Software_cup\teacher_app\views.py", line 746, in create_exercise
    return render(request, 'create_exercise.html', context)
           ^^^^^^^^^^^^^^^^^^^^^^^^^^^^^^^^^^^^^^^^^^^^^^^^
  File "D:\GitHub\Project\Software_cup\venv\Lib\site-packages\django\shortcuts.py", line 25, in render
    content = loader.render_to_string(template_name, context, request, using=using)
              ^^^^^^^^^^^^^^^^^^^^^^^^^^^^^^^^^^^^^^^^^^^^^^^^^^^^^^^^^^^^^^^^^^^^^
  File "D:\GitHub\Project\Software_cup\venv\Lib\site-packages\django\template\loader.py", line 61, in render_to_string
    template = get_template(template_name, using=using)
               ^^^^^^^^^^^^^^^^^^^^^^^^^^^^^^^^^^^^^^^^
  File "D:\GitHub\Project\Software_cup\venv\Lib\site-packages\django\template\loader.py", line 15, in get_template
    return engine.get_template(template_name)
           ^^^^^^^^^^^^^^^^^^^^^^^^^^^^^^^^^^
  File "D:\GitHub\Project\Software_cup\venv\Lib\site-packages\django\template\backends\django.py", line 33, in get_template
    return Template(self.engine.get_template(template_name), self)
                    ^^^^^^^^^^^^^^^^^^^^^^^^^^^^^^^^^^^^^^^
  File "D:\GitHub\Project\Software_cup\venv\Lib\site-packages\django\template\engine.py", line 177, in get_template
    template, origin = self.find_template(template_name)
                       ^^^^^^^^^^^^^^^^^^^^^^^^^^^^^^^^^
  File "D:\GitHub\Project\Software_cup\venv\Lib\site-packages\django\template\engine.py", line 159, in find_template
    template = loader.get_template(name, skip=skip)
               ^^^^^^^^^^^^^^^^^^^^^^^^^^^^^^^^^^^^
  File "D:\GitHub\Project\Software_cup\venv\Lib\site-packages\django\template\loaders\cached.py", line 57, in get_template
    template = super().get_template(template_name, skip)
               ^^^^^^^^^^^^^^^^^^^^^^^^^^^^^^^^^^^^^^^^^
  File "D:\GitHub\Project\Software_cup\venv\Lib\site-packages\django\template\loaders\base.py", line 28, in get_template
    return Template(
           ^^^^^^^^^
  File "D:\GitHub\Project\Software_cup\venv\Lib\site-packages\django\template\base.py", line 154, in __init__
    self.nodelist = self.compile_nodelist()
                    ^^^^^^^^^^^^^^^^^^^^^^^
  File "D:\GitHub\Project\Software_cup\venv\Lib\site-packages\django\template\base.py", line 196, in compile_nodelist
    return parser.parse()
           ^^^^^^^^^^^^^^
  File "D:\GitHub\Project\Software_cup\venv\Lib\site-packages\django\template\base.py", line 510, in parse
    raise self.error(token, e)
  File "D:\GitHub\Project\Software_cup\venv\Lib\site-packages\django\template\base.py", line 508, in parse
    compiled_result = compile_func(self, token)
                      ^^^^^^^^^^^^^^^^^^^^^^^^^
  File "D:\GitHub\Project\Software_cup\venv\Lib\site-packages\django\template\loader_tags.py", line 295, in do_extends
    nodelist = parser.parse()
               ^^^^^^^^^^^^^^
  File "D:\GitHub\Project\Software_cup\venv\Lib\site-packages\django\template\base.py", line 510, in parse
    raise self.error(token, e)
  File "D:\GitHub\Project\Software_cup\venv\Lib\site-packages\django\template\base.py", line 508, in parse
    compiled_result = compile_func(self, token)
                      ^^^^^^^^^^^^^^^^^^^^^^^^^
  File "D:\GitHub\Project\Software_cup\venv\Lib\site-packages\django\template\loader_tags.py", line 234, in do_block
    nodelist = parser.parse(("endblock",))
               ^^^^^^^^^^^^^^^^^^^^^^^^^^^
  File "D:\GitHub\Project\Software_cup\venv\Lib\site-packages\django\template\base.py", line 510, in parse
    raise self.error(token, e)
  File "D:\GitHub\Project\Software_cup\venv\Lib\site-packages\django\template\base.py", line 508, in parse
    compiled_result = compile_func(self, token)
                      ^^^^^^^^^^^^^^^^^^^^^^^^^
  File "D:\GitHub\Project\Software_cup\venv\Lib\site-packages\django\template\defaulttags.py", line 861, in do_for
    nodelist_loop = parser.parse(
                    ^^^^^^^^^^^^^
  File "D:\GitHub\Project\Software_cup\venv\Lib\site-packages\django\template\base.py", line 504, in parse
    self.invalid_block_tag(token, command, parse_until)
  File "D:\GitHub\Project\Software_cup\venv\Lib\site-packages\django\template\base.py", line 555, in invalid_block_tag
    raise self.error(
django.template.exceptions.TemplateSyntaxError: Invalid block tag on line 167: 'static', expected 'empty' or 'endfor'. Did you forget to register or load this tag?
ERROR 2024-10-30 19:46:14,937 basehttp "GET /teacher/repository/exercise_list/create_exercise/61/ HTTP/1.1" 500 218146
ERROR 2024-11-02 21:30:52,974 log Internal Server Error: /teacher/repository/exercise_list/create_exercise/68/
Traceback (most recent call last):
  File "D:\GitHub\Project\Software_cup\venv\Lib\site-packages\pandas\core\indexes\range.py", line 1018, in __getitem__
    return self._range[new_key]
           ~~~~~~~~~~~^^^^^^^^^
IndexError: range object index out of range

The above exception was the direct cause of the following exception:

Traceback (most recent call last):
  File "D:\GitHub\Project\Software_cup\teacher_app\views.py", line 736, in create_exercise
    if df.columns[0] != 'input' or df.columns[1] != 'output':
       ~~~~~~~~~~^^^
  File "D:\GitHub\Project\Software_cup\venv\Lib\site-packages\pandas\core\indexes\range.py", line 1020, in __getitem__
    raise IndexError(
IndexError: index 0 is out of bounds for axis 0 with size 0

During handling of the above exception, another exception occurred:

Traceback (most recent call last):
  File "D:\GitHub\Project\Software_cup\venv\Lib\site-packages\django\core\handlers\exception.py", line 55, in inner
    response = get_response(request)
               ^^^^^^^^^^^^^^^^^^^^^
  File "D:\GitHub\Project\Software_cup\venv\Lib\site-packages\django\core\handlers\base.py", line 197, in _get_response
    response = wrapped_callback(request, *callback_args, **callback_kwargs)
               ^^^^^^^^^^^^^^^^^^^^^^^^^^^^^^^^^^^^^^^^^^^^^^^^^^^^^^^^^^^^
  File "D:\GitHub\Project\Software_cup\login\views.py", line 88, in wrapper
    return view_func(request, *args, **kwargs)
           ^^^^^^^^^^^^^^^^^^^^^^^^^^^^^^^^^^^
  File "D:\GitHub\Project\Software_cup\teacher_app\views.py", line 762, in create_exercise
    ExerciseQuestionTestCase.objects.filter(question=question).delete()
    ^^^^^^^^^^^^^^^^^^^^^^^^^^^^^^^^^^^^^^^^^^^^^^^^^^^^^^^^^^
  File "D:\GitHub\Project\Software_cup\venv\Lib\site-packages\django\db\models\manager.py", line 87, in manager_method
    return getattr(self.get_queryset(), name)(*args, **kwargs)
           ^^^^^^^^^^^^^^^^^^^^^^^^^^^^^^^^^^^^^^^^^^^^^^^^^^^
  File "D:\GitHub\Project\Software_cup\venv\Lib\site-packages\django\db\models\query.py", line 1476, in filter
    return self._filter_or_exclude(False, args, kwargs)
           ^^^^^^^^^^^^^^^^^^^^^^^^^^^^^^^^^^^^^^^^^^^^
  File "D:\GitHub\Project\Software_cup\venv\Lib\site-packages\django\db\models\query.py", line 1494, in _filter_or_exclude
    clone._filter_or_exclude_inplace(negate, args, kwargs)
  File "D:\GitHub\Project\Software_cup\venv\Lib\site-packages\django\db\models\query.py", line 1501, in _filter_or_exclude_inplace
    self._query.add_q(Q(*args, **kwargs))
  File "D:\GitHub\Project\Software_cup\venv\Lib\site-packages\django\db\models\sql\query.py", line 1613, in add_q
    clause, _ = self._add_q(q_object, self.used_aliases)
                ^^^^^^^^^^^^^^^^^^^^^^^^^^^^^^^^^^^^^^^^
  File "D:\GitHub\Project\Software_cup\venv\Lib\site-packages\django\db\models\sql\query.py", line 1645, in _add_q
    child_clause, needed_inner = self.build_filter(
                                 ^^^^^^^^^^^^^^^^^^
  File "D:\GitHub\Project\Software_cup\venv\Lib\site-packages\django\db\models\sql\query.py", line 1559, in build_filter
    condition = self.build_lookup(lookups, col, value)
                ^^^^^^^^^^^^^^^^^^^^^^^^^^^^^^^^^^^^^^
  File "D:\GitHub\Project\Software_cup\venv\Lib\site-packages\django\db\models\sql\query.py", line 1389, in build_lookup
    lookup = lookup_class(lhs, rhs)
             ^^^^^^^^^^^^^^^^^^^^^^
  File "D:\GitHub\Project\Software_cup\venv\Lib\site-packages\django\db\models\lookups.py", line 30, in __init__
    self.rhs = self.get_prep_lookup()
               ^^^^^^^^^^^^^^^^^^^^^^
  File "D:\GitHub\Project\Software_cup\venv\Lib\site-packages\django\db\models\fields\related_lookups.py", line 147, in get_prep_lookup
    self.rhs = get_normalized_value(self.rhs, self.lhs)[0]
               ^^^^^^^^^^^^^^^^^^^^^^^^^^^^^^^^^^^^^^^^
  File "D:\GitHub\Project\Software_cup\venv\Lib\site-packages\django\db\models\fields\related_lookups.py", line 45, in get_normalized_value
    raise ValueError("Model instances passed to related filters must be saved.")
ValueError: Model instances passed to related filters must be saved.
ERROR 2024-11-02 21:30:52,982 basehttp "POST /teacher/repository/exercise_list/create_exercise/68/ HTTP/1.1" 500 152293
ERROR 2024-11-02 21:31:36,023 log Internal Server Error: /teacher/repository/exercise_list/create_exercise/69/
Traceback (most recent call last):
  File "D:\GitHub\Project\Software_cup\venv\Lib\site-packages\pandas\core\indexes\range.py", line 1018, in __getitem__
    return self._range[new_key]
           ~~~~~~~~~~~^^^^^^^^^
IndexError: range object index out of range

The above exception was the direct cause of the following exception:

Traceback (most recent call last):
  File "D:\GitHub\Project\Software_cup\teacher_app\views.py", line 736, in create_exercise
    if df.columns[0] != 'input' or df.columns[1] != 'output':
       ~~~~~~~~~~^^^
  File "D:\GitHub\Project\Software_cup\venv\Lib\site-packages\pandas\core\indexes\range.py", line 1020, in __getitem__
    raise IndexError(
IndexError: index 0 is out of bounds for axis 0 with size 0

During handling of the above exception, another exception occurred:

Traceback (most recent call last):
  File "D:\GitHub\Project\Software_cup\venv\Lib\site-packages\django\core\handlers\exception.py", line 55, in inner
    response = get_response(request)
               ^^^^^^^^^^^^^^^^^^^^^
  File "D:\GitHub\Project\Software_cup\venv\Lib\site-packages\django\core\handlers\base.py", line 197, in _get_response
    response = wrapped_callback(request, *callback_args, **callback_kwargs)
               ^^^^^^^^^^^^^^^^^^^^^^^^^^^^^^^^^^^^^^^^^^^^^^^^^^^^^^^^^^^^
  File "D:\GitHub\Project\Software_cup\login\views.py", line 88, in wrapper
    return view_func(request, *args, **kwargs)
           ^^^^^^^^^^^^^^^^^^^^^^^^^^^^^^^^^^^
  File "D:\GitHub\Project\Software_cup\teacher_app\views.py", line 762, in create_exercise
    ExerciseQuestionTestCase.objects.filter(question=question).delete()
    ^^^^^^^^^^^^^^^^^^^^^^^^^^^^^^^^^^^^^^^^^^^^^^^^^^^^^^^^^^
  File "D:\GitHub\Project\Software_cup\venv\Lib\site-packages\django\db\models\manager.py", line 87, in manager_method
    return getattr(self.get_queryset(), name)(*args, **kwargs)
           ^^^^^^^^^^^^^^^^^^^^^^^^^^^^^^^^^^^^^^^^^^^^^^^^^^^
  File "D:\GitHub\Project\Software_cup\venv\Lib\site-packages\django\db\models\query.py", line 1476, in filter
    return self._filter_or_exclude(False, args, kwargs)
           ^^^^^^^^^^^^^^^^^^^^^^^^^^^^^^^^^^^^^^^^^^^^
  File "D:\GitHub\Project\Software_cup\venv\Lib\site-packages\django\db\models\query.py", line 1494, in _filter_or_exclude
    clone._filter_or_exclude_inplace(negate, args, kwargs)
  File "D:\GitHub\Project\Software_cup\venv\Lib\site-packages\django\db\models\query.py", line 1501, in _filter_or_exclude_inplace
    self._query.add_q(Q(*args, **kwargs))
  File "D:\GitHub\Project\Software_cup\venv\Lib\site-packages\django\db\models\sql\query.py", line 1613, in add_q
    clause, _ = self._add_q(q_object, self.used_aliases)
                ^^^^^^^^^^^^^^^^^^^^^^^^^^^^^^^^^^^^^^^^
  File "D:\GitHub\Project\Software_cup\venv\Lib\site-packages\django\db\models\sql\query.py", line 1645, in _add_q
    child_clause, needed_inner = self.build_filter(
                                 ^^^^^^^^^^^^^^^^^^
  File "D:\GitHub\Project\Software_cup\venv\Lib\site-packages\django\db\models\sql\query.py", line 1559, in build_filter
    condition = self.build_lookup(lookups, col, value)
                ^^^^^^^^^^^^^^^^^^^^^^^^^^^^^^^^^^^^^^
  File "D:\GitHub\Project\Software_cup\venv\Lib\site-packages\django\db\models\sql\query.py", line 1389, in build_lookup
    lookup = lookup_class(lhs, rhs)
             ^^^^^^^^^^^^^^^^^^^^^^
  File "D:\GitHub\Project\Software_cup\venv\Lib\site-packages\django\db\models\lookups.py", line 30, in __init__
    self.rhs = self.get_prep_lookup()
               ^^^^^^^^^^^^^^^^^^^^^^
  File "D:\GitHub\Project\Software_cup\venv\Lib\site-packages\django\db\models\fields\related_lookups.py", line 147, in get_prep_lookup
    self.rhs = get_normalized_value(self.rhs, self.lhs)[0]
               ^^^^^^^^^^^^^^^^^^^^^^^^^^^^^^^^^^^^^^^^
  File "D:\GitHub\Project\Software_cup\venv\Lib\site-packages\django\db\models\fields\related_lookups.py", line 45, in get_normalized_value
    raise ValueError("Model instances passed to related filters must be saved.")
ValueError: Model instances passed to related filters must be saved.
ERROR 2024-11-02 21:31:36,056 basehttp "POST /teacher/repository/exercise_list/create_exercise/69/ HTTP/1.1" 500 152293
